Forbidden: /
Forbidden: /
Forbidden: /
Forbidden: /
Forbidden: /
Forbidden: /
Forbidden: /
Forbidden: /
Forbidden: /
Forbidden: /
Forbidden: /
Forbidden: /
Forbidden: /
Forbidden: /
Forbidden: /
Forbidden: /
Forbidden: /post/1/
Forbidden: /post/1/
Forbidden: /post/1/
Forbidden: /post/1/
Forbidden: /post/1/
Forbidden: /post/1/
Forbidden: /post/999/
Forbidden: /post/1/
Forbidden: /post/1/
Forbidden: /post/1/
Forbidden: /post/1/
Forbidden: /post/1/
Forbidden: /post/1/
Forbidden: /post/1/
Forbidden: /post/1/
Forbidden: /post/1/
Forbidden: /post/1/
Forbidden: /post/1/
Forbidden: /post/1/
Forbidden: /post/1/
Forbidden: /post/1/
Forbidden: /post/1/
Internal Server Error: /post/999/
Traceback (most recent call last):
  File "/Users/shivamsri/.pyenv/versions/3.8.10/lib/python3.8/site-packages/django/core/handlers/exception.py", line 55, in inner
    response = get_response(request)
  File "/Users/shivamsri/.pyenv/versions/3.8.10/lib/python3.8/site-packages/django/core/handlers/base.py", line 197, in _get_response
    response = wrapped_callback(request, *callback_args, **callback_kwargs)
  File "/Users/shivamsri/.pyenv/versions/3.8.10/lib/python3.8/site-packages/django/utils/decorators.py", line 134, in _wrapper_view
    response = view_func(request, *args, **kwargs)
  File "/Users/shivamsri/Documents/zigsaw/django/final/question_13/solved/django_questions/library/views.py", line 9, in blog_post_detail
    post = BlogPost.objects.get(id=post_id)
  File "/Users/shivamsri/.pyenv/versions/3.8.10/lib/python3.8/site-packages/django/db/models/manager.py", line 87, in manager_method
    return getattr(self.get_queryset(), name)(*args, **kwargs)
  File "/Users/shivamsri/.pyenv/versions/3.8.10/lib/python3.8/site-packages/django/db/models/query.py", line 637, in get
    raise self.model.DoesNotExist(
library.models.BlogPost.DoesNotExist: BlogPost matching query does not exist.
Internal Server Error: /post/999/
Traceback (most recent call last):
  File "/Users/shivamsri/.pyenv/versions/3.8.10/lib/python3.8/site-packages/django/core/handlers/exception.py", line 55, in inner
    response = get_response(request)
  File "/Users/shivamsri/.pyenv/versions/3.8.10/lib/python3.8/site-packages/django/core/handlers/base.py", line 197, in _get_response
    response = wrapped_callback(request, *callback_args, **callback_kwargs)
  File "/Users/shivamsri/.pyenv/versions/3.8.10/lib/python3.8/site-packages/django/utils/decorators.py", line 134, in _wrapper_view
    response = view_func(request, *args, **kwargs)
  File "/Users/shivamsri/Documents/zigsaw/django/final/question_13/solved/django_questions/library/views.py", line 9, in blog_post_detail
    post = BlogPost.objects.get(id=post_id)
  File "/Users/shivamsri/.pyenv/versions/3.8.10/lib/python3.8/site-packages/django/db/models/manager.py", line 87, in manager_method
    return getattr(self.get_queryset(), name)(*args, **kwargs)
  File "/Users/shivamsri/.pyenv/versions/3.8.10/lib/python3.8/site-packages/django/db/models/query.py", line 637, in get
    raise self.model.DoesNotExist(
library.models.BlogPost.DoesNotExist: BlogPost matching query does not exist.
Internal Server Error: /post/999/
Traceback (most recent call last):
  File "/Users/shivamsri/.pyenv/versions/3.8.10/lib/python3.8/site-packages/django/core/handlers/exception.py", line 55, in inner
    response = get_response(request)
  File "/Users/shivamsri/.pyenv/versions/3.8.10/lib/python3.8/site-packages/django/core/handlers/base.py", line 197, in _get_response
    response = wrapped_callback(request, *callback_args, **callback_kwargs)
  File "/Users/shivamsri/.pyenv/versions/3.8.10/lib/python3.8/site-packages/django/utils/decorators.py", line 134, in _wrapper_view
    response = view_func(request, *args, **kwargs)
  File "/Users/shivamsri/Documents/zigsaw/django/final/question_13/solved/django_questions/library/views.py", line 9, in blog_post_detail
    post = BlogPost.objects.get(id=post_id)
  File "/Users/shivamsri/.pyenv/versions/3.8.10/lib/python3.8/site-packages/django/db/models/manager.py", line 87, in manager_method
    return getattr(self.get_queryset(), name)(*args, **kwargs)
  File "/Users/shivamsri/.pyenv/versions/3.8.10/lib/python3.8/site-packages/django/db/models/query.py", line 637, in get
    raise self.model.DoesNotExist(
library.models.BlogPost.DoesNotExist: BlogPost matching query does not exist.
Internal Server Error: /post/999/
Traceback (most recent call last):
  File "/Users/shivamsri/.pyenv/versions/3.8.10/lib/python3.8/site-packages/django/core/handlers/exception.py", line 55, in inner
    response = get_response(request)
  File "/Users/shivamsri/.pyenv/versions/3.8.10/lib/python3.8/site-packages/django/core/handlers/base.py", line 197, in _get_response
    response = wrapped_callback(request, *callback_args, **callback_kwargs)
  File "/Users/shivamsri/.pyenv/versions/3.8.10/lib/python3.8/site-packages/django/utils/decorators.py", line 134, in _wrapper_view
    response = view_func(request, *args, **kwargs)
  File "/Users/shivamsri/Documents/zigsaw/django/final/question_13/solved/django_questions/library/views.py", line 9, in blog_post_detail
    post = BlogPost.objects.get(id=post_id)
  File "/Users/shivamsri/.pyenv/versions/3.8.10/lib/python3.8/site-packages/django/db/models/manager.py", line 87, in manager_method
    return getattr(self.get_queryset(), name)(*args, **kwargs)
  File "/Users/shivamsri/.pyenv/versions/3.8.10/lib/python3.8/site-packages/django/db/models/query.py", line 637, in get
    raise self.model.DoesNotExist(
library.models.BlogPost.DoesNotExist: BlogPost matching query does not exist.
Internal Server Error: /register/
Traceback (most recent call last):
  File "/Users/shivamsri/.pyenv/versions/3.8.10/lib/python3.8/site-packages/django/core/handlers/exception.py", line 55, in inner
    response = get_response(request)
  File "/Users/shivamsri/.pyenv/versions/3.8.10/lib/python3.8/site-packages/django/core/handlers/base.py", line 197, in _get_response
    response = wrapped_callback(request, *callback_args, **callback_kwargs)
  File "/Users/shivamsri/Documents/zigsaw/django/final/question_14/solved/django_questions/library/views.py", line 38, in register
    if form.clean_email():
  File "/Users/shivamsri/Documents/zigsaw/django/final/question_14/solved/django_questions/library/views.py", line 20, in clean_email
    email = self.cleaned_data['email']
AttributeError: 'RegistrationForm' object has no attribute 'cleaned_data'
Internal Server Error: /register/
Traceback (most recent call last):
  File "/Users/shivamsri/.pyenv/versions/3.8.10/lib/python3.8/site-packages/django/core/handlers/exception.py", line 55, in inner
    response = get_response(request)
  File "/Users/shivamsri/.pyenv/versions/3.8.10/lib/python3.8/site-packages/django/core/handlers/base.py", line 197, in _get_response
    response = wrapped_callback(request, *callback_args, **callback_kwargs)
  File "/Users/shivamsri/Documents/zigsaw/django/final/question_14/solved/django_questions/library/views.py", line 38, in register
    if form.clean_email():
  File "/Users/shivamsri/Documents/zigsaw/django/final/question_14/solved/django_questions/library/views.py", line 20, in clean_email
    email = self.cleaned_data['email']
AttributeError: 'RegistrationForm' object has no attribute 'cleaned_data'
Internal Server Error: /register/
Traceback (most recent call last):
  File "/Users/shivamsri/.pyenv/versions/3.8.10/lib/python3.8/site-packages/django/core/handlers/exception.py", line 55, in inner
    response = get_response(request)
  File "/Users/shivamsri/.pyenv/versions/3.8.10/lib/python3.8/site-packages/django/core/handlers/base.py", line 197, in _get_response
    response = wrapped_callback(request, *callback_args, **callback_kwargs)
  File "/Users/shivamsri/Documents/zigsaw/django/final/question_14/solved/django_questions/library/views.py", line 35, in register
    if form.clean_email():
  File "/Users/shivamsri/Documents/zigsaw/django/final/question_14/solved/django_questions/library/views.py", line 20, in clean_email
    email = self.cleaned_data['email']
AttributeError: 'RegistrationForm' object has no attribute 'cleaned_data'
Internal Server Error: /register/
Traceback (most recent call last):
  File "/Users/shivamsri/.pyenv/versions/3.8.10/lib/python3.8/site-packages/django/core/handlers/exception.py", line 55, in inner
    response = get_response(request)
  File "/Users/shivamsri/.pyenv/versions/3.8.10/lib/python3.8/site-packages/django/core/handlers/base.py", line 197, in _get_response
    response = wrapped_callback(request, *callback_args, **callback_kwargs)
  File "/Users/shivamsri/Documents/zigsaw/django/final/question_14/solved/django_questions/library/views.py", line 35, in register
    if form.clean_email():
  File "/Users/shivamsri/Documents/zigsaw/django/final/question_14/solved/django_questions/library/views.py", line 20, in clean_email
    email = self.cleaned_data['email']
AttributeError: 'RegistrationForm' object has no attribute 'cleaned_data'
Internal Server Error: /register/
Traceback (most recent call last):
  File "/Users/shivamsri/.pyenv/versions/3.8.10/lib/python3.8/site-packages/django/core/handlers/exception.py", line 55, in inner
    response = get_response(request)
  File "/Users/shivamsri/.pyenv/versions/3.8.10/lib/python3.8/site-packages/django/core/handlers/base.py", line 204, in _get_response
    self.check_response(response, callback)
  File "/Users/shivamsri/.pyenv/versions/3.8.10/lib/python3.8/site-packages/django/core/handlers/base.py", line 332, in check_response
    raise ValueError(
ValueError: The view library.views.register didn't return an HttpResponse object. It returned None instead.
Internal Server Error: /register/
Traceback (most recent call last):
  File "/Users/shivamsri/.pyenv/versions/3.8.10/lib/python3.8/site-packages/django/core/handlers/exception.py", line 55, in inner
    response = get_response(request)
  File "/Users/shivamsri/.pyenv/versions/3.8.10/lib/python3.8/site-packages/django/core/handlers/base.py", line 204, in _get_response
    self.check_response(response, callback)
  File "/Users/shivamsri/.pyenv/versions/3.8.10/lib/python3.8/site-packages/django/core/handlers/base.py", line 332, in check_response
    raise ValueError(
ValueError: The view library.views.register didn't return an HttpResponse object. It returned None instead.
Internal Server Error: /register/
Traceback (most recent call last):
  File "/Users/shivamsri/.pyenv/versions/3.8.10/lib/python3.8/site-packages/django/core/handlers/exception.py", line 55, in inner
    response = get_response(request)
  File "/Users/shivamsri/.pyenv/versions/3.8.10/lib/python3.8/site-packages/django/core/handlers/base.py", line 204, in _get_response
    self.check_response(response, callback)
  File "/Users/shivamsri/.pyenv/versions/3.8.10/lib/python3.8/site-packages/django/core/handlers/base.py", line 332, in check_response
    raise ValueError(
ValueError: The view library.views.register didn't return an HttpResponse object. It returned None instead.
